Workbook

Sheet 📊 All Years
B1: 📊 All-Years Dashboard | May 2026 – Jun 2028 — Expense Tracker
B2: Auto-updates from all month tabs · Adjust paychecks & budgets in each tab · Negative = overspent
B4: Month | C4: Paycheck $ | D4: Carry-Over | E4: Total Avail | F4: Going Out $ | G4: Invested | H4: Ally Added | I4: Left Over $ | J4: Ally Balance
B6: ── 2026 (May – Dec) ──
B7: May 2026 | C7: ='May 2026'!D6+'May 2026'!H6 | D7: ='May 2026'!D9 | E7: ='May 2026'!H8 | F7: ='May 2026'!D64 | G7: ='May 2026'!D54 | H7: ='May 2026'!D53 | I7: ='May 2026'!D65 | J7: ='May 2026'!F53
B8: Jun 2026 | C8: ='Jun 2026'!D6+'Jun 2026'!H6 | D8: ='Jun 2026'!D9 | E8: ='Jun 2026'!H8 | F8: ='Jun 2026'!D64 | G8: ='Jun 2026'!D54 | H8: ='Jun 2026'!D53 | I8: ='Jun 2026'!D65 | J8: ='Jun 2026'!F53
B9: Jul 2026 | C9: ='Jul 2026'!D6+'Jul 2026'!H6 | D9: ='Jul 2026'!D9 | E9: ='Jul 2026'!H8 | F9: ='Jul 2026'!D64 | G9: ='Jul 2026'!D54 | H9: ='Jul 2026'!D53 | I9: ='Jul 2026'!D65 | J9: ='Jul 2026'!F53
B10: Aug 2026 | C10: ='Aug 2026'!D6+'Aug 2026'!H6 | D10: ='Aug 2026'!D9 | E10: ='Aug 2026'!H8 | F10: ='Aug 2026'!D64 | G10: ='Aug 2026'!D54 | H10: ='Aug 2026'!D53 | I10: ='Aug 2026'!D65 | J10: ='Aug 2026'!F53
B11: Sep 2026 | C11: ='Sep 2026'!D6+'Sep 2026'!H6 | D11: ='Sep 2026'!D9 | E11: ='Sep 2026'!H8 | F11: ='Sep 2026'!D64 | G11: ='Sep 2026'!D54 | H11: ='Sep 2026'!D53 | I11: ='Sep 2026'!D65 | J11: ='Sep 2026'!F53
B12: Oct 2026 | C12: ='Oct 2026'!D6+'Oct 2026'!H6 | D12: ='Oct 2026'!D9 | E12: ='Oct 2026'!H8 | F12: ='Oct 2026'!D64 | G12: ='Oct 2026'!D54 | H12: ='Oct 2026'!D53 | I12: ='Oct 2026'!D65 | J12: ='Oct 2026'!F53
B13: Nov 2026 | C13: ='Nov 2026'!D6+'Nov 2026'!H6 | D13: ='Nov 2026'!D9 | E13: ='Nov 2026'!H8 | F13: ='Nov 2026'!D64 | G13: ='Nov 2026'!D54 | H13: ='Nov 2026'!D53 | I13: ='Nov 2026'!D65 | J13: ='Nov 2026'!F53
B14: Dec 2026 | C14: ='Dec 2026'!D6+'Dec 2026'!H6 | D14: ='Dec 2026'!D9 | E14: ='Dec 2026'!H8 | F14: ='Dec 2026'!D64 | G14: ='Dec 2026'!D54 | H14: ='Dec 2026'!D53 | I14: ='Dec 2026'!D65 | J14: ='Dec 2026'!F53
B15: 2026 Total | C15: =SUM(C7:C14) | E15: =SUM(E7:E14) | F15: =SUM(F7:F14) | G15: =SUM(G7:G14) | H15: =SUM(H7:H14) | I15: =SUM(I7:I14) | J15: =MAX(J7:J14)
B17: ── 2027 (Full Year) ──
B18: Jan 2027 | C18: ='Jan 2027'!D6+'Jan 2027'!H6 | D18: ='Jan 2027'!D9 | E18: ='Jan 2027'!H8 | F18: ='Jan 2027'!D64 | G18: ='Jan 2027'!D54 | H18: ='Jan 2027'!D53 | I18: ='Jan 2027'!D65 | J18: ='Jan 2027'!F53
B19: Feb 2027 | C19: ='Feb 2027'!D6+'Feb 2027'!H6 | D19: ='Feb 2027'!D9 | E19: ='Feb 2027'!H8 | F19: ='Feb 2027'!D64 | G19: ='Feb 2027'!D54 | H19: ='Feb 2027'!D53 | I19: ='Feb 2027'!D65 | J19: ='Feb 2027'!F53
B20: Mar 2027 | C20: ='Mar 2027'!D6+'Mar 2027'!H6 | D20: ='Mar 2027'!D9 | E20: ='Mar 2027'!H8 | F20: ='Mar 2027'!D64 | G20: ='Mar 2027'!D54 | H20: ='Mar 2027'!D53 | I20: ='Mar 2027'!D65 | J20: ='Mar 2027'!F53
B21: Apr 2027 | C21: ='Apr 2027'!D6+'Apr 2027'!H6 | D21: ='Apr 2027'!D9 | E21: ='Apr 2027'!H8 | F21: ='Apr 2027'!D64 | G21: ='Apr 2027'!D54 | H21: ='Apr 2027'!D53 | I21: ='Apr 2027'!D65 | J21: ='Apr 2027'!F53
B22: May 2027 | C22: ='May 2027'!D6+'May 2027'!H6 | D22: ='May 2027'!D9 | E22: ='May 2027'!H8 | F22: ='May 2027'!D64 | G22: ='May 2027'!D54 | H22: ='May 2027'!D53 | I22: ='May 2027'!D65 | J22: ='May 2027'!F53
B23: Jun 2027 | C23: ='Jun 2027'!D6+'Jun 2027'!H6 | D23: ='Jun 2027'!D9 | E23: ='Jun 2027'!H8 | F23: ='Jun 2027'!D64 | G23: ='Jun 2027'!D54 | H23: ='Jun 2027'!D53 | I23: ='Jun 2027'!D65 | J23: ='Jun 2027'!F53
B24: Jul 2027 | C24: ='Jul 2027'!D6+'Jul 2027'!H6 | D24: ='Jul 2027'!D9 | E24: ='Jul 2027'!H8 | F24: ='Jul 2027'!D64 | G24: ='Jul 2027'!D54 | H24: ='Jul 2027'!D53 | I24: ='Jul 2027'!D65 | J24: ='Jul 2027'!F53
B25: Aug 2027 | C25: ='Aug 2027'!D6+'Aug 2027'!H6 | D25: ='Aug 2027'!D9 | E25: ='Aug 2027'!H8 | F25: ='Aug 2027'!D64 | G25: ='Aug 2027'!D54 | H25: ='Aug 2027'!D53 | I25: ='Aug 2027'!D65 | J25: ='Aug 2027'!F53
B26: Sep 2027 | C26: ='Sep 2027'!D6+'Sep 2027'!H6 | D26: ='Sep 2027'!D9 | E26: ='Sep 2027'!H8 | F26: ='Sep 2027'!D64 | G26: ='Sep 2027'!D54 | H26: ='Sep 2027'!D53 | I26: ='Sep 2027'!D65 | J26: ='Sep 2027'!F53
B27: Oct 2027 | C27: ='Oct 2027'!D6+'Oct 2027'!H6 | D27: ='Oct 2027'!D9 | E27: ='Oct 2027'!H8 | F27: ='Oct 2027'!D64 | G27: ='Oct 2027'!D54 | H27: ='Oct 2027'!D53 | I27: ='Oct 2027'!D65 | J27: ='Oct 2027'!F53
B28: Nov 2027 | C28: ='Nov 2027'!D6+'Nov 2027'!H6 | D28: ='Nov 2027'!D9 | E28: ='Nov 2027'!H8 | F28: ='Nov 2027'!D64 | G28: ='Nov 2027'!D54 | H28: ='Nov 2027'!D53 | I28: ='Nov 2027'!D65 | J28: ='Nov 2027'!F53
B29: Dec 2027 | C29: ='Dec 2027'!D6+'Dec 2027'!H6 | D29: ='Dec 2027'!D9 | E29: ='Dec 2027'!H8 | F29: ='Dec 2027'!D64 | G29: ='Dec 2027'!D54 | H29: ='Dec 2027'!D53 | I29: ='Dec 2027'!D65 | J29: ='Dec 2027'!F53
B30: 2027 Total | C30: =SUM(C18:C29) | E30: =SUM(E18:E29) | F30: =SUM(F18:F29) | G30: =SUM(G18:G29) | H30: =SUM(H18:H29) | I30: =SUM(I18:I29) | J30: =MAX(J18:J29)
B32: ── 2028 (Jan – Jun) ──
B33: Jan 2028 | C33: ='Jan 2028'!D6+'Jan 2028'!H6 | D33: ='Jan 2028'!D9 | E33: ='Jan 2028'!H8 | F33: ='Jan 2028'!D64 | G33: ='Jan 2028'!D54 | H33: ='Jan 2028'!D53 | I33: ='Jan 2028'!D65 | J33: ='Jan 2028'!F53
B34: Feb 2028 | C34: ='Feb 2028'!D6+'Feb 2028'!H6 | D34: ='Feb 2028'!D9 | E34: ='Feb 2028'!H8 | F34: ='Feb 2028'!D64 | G34: ='Feb 2028'!D54 | H34: ='Feb 2028'!D53 | I34: ='Feb 2028'!D65 | J34: ='Feb 2028'!F53
B35: Mar 2028 | C35: ='Mar 2028'!D6+'Mar 2028'!H6 | D35: ='Mar 2028'!D9 | E35: ='Mar 2028'!H8 | F35: ='Mar 2028'!D64 | G35: ='Mar 2028'!D54 | H35: ='Mar 2028'!D53 | I35: ='Mar 2028'!D65 | J35: ='Mar 2028'!F53
B36: Apr 2028 | C36: ='Apr 2028'!D6+'Apr 2028'!H6 | D36: ='Apr 2028'!D9 | E36: ='Apr 2028'!H8 | F36: ='Apr 2028'!D64 | G36: ='Apr 2028'!D54 | H36: ='Apr 2028'!D53 | I36: ='Apr 2028'!D65 | J36: ='Apr 2028'!F53
B37: May 2028 | C37: ='May 2028'!D6+'May 2028'!H6 | D37: ='May 2028'!D9 | E37: ='May 2028'!H8 | F37: ='May 2028'!D64 | G37: ='May 2028'!D54 | H37: ='May 2028'!D53 | I37: ='May 2028'!D65 | J37: ='May 2028'!F53
B38: Jun 2028 | C38: ='Jun 2028'!D6+'Jun 2028'!H6 | D38: ='Jun 2028'!D9 | E38: ='Jun 2028'!H8 | F38: ='Jun 2028'!D64 | G38: ='Jun 2028'!D54 | H38: ='Jun 2028'!D53 | I38: ='Jun 2028'!D65 | J38: ='Jun 2028'!F53
B39: 2028 Total | C39: =SUM(C33:C38) | E39: =SUM(E33:E38) | F39: =SUM(F33:F38) | G39: =SUM(G33:G38) | H39: =SUM(H33:H38) | I39: =SUM(I33:I38) | J39: =MAX(J33:J38)
B41: All-Years Grand Total | C41: =SUM(C5:C39) | E41: =SUM(E5:E39) | F41: =SUM(F5:F39) | G41: =SUM(G5:G39) | H41: =SUM(H5:H39) | I41: =SUM(I5:I39)

Sheet 📈 Projections 2026
B1: 📈 2026 Month-by-Month Comparison & Year-End Projection
B2: Actuals through current month · Remaining months = pre-planned expenses only · Year-end = Dec leftover
B3: Category / Metric | C3: May | D3: Jun | E3: Jul | F3: Aug | G3: Sep | H3: Oct | I3: Nov | J3: Dec | K3: Avg/Mo | L3: Year-End Proj | M3: Budget
B4: 📥 INCOME
B5: Paycheck Income (excl. carry-over) | C5: ='May 2026'!D6+'May 2026'!H6 -> 4167.35 | D5: ='Jun 2026'!D6+'Jun 2026'!H6 -> 3959.1 | E5: ='Jul 2026'!D6+'Jul 2026'!H6 -> 4270.42 | F5: ='Aug 2026'!D6+'Aug 2026'!H6 -> 5000 | G5: ='Sep 2026'!D6+'Sep 2026'!H6 -> 5000 | H5: ='Oct 2026'!D6+'Oct 2026'!H6 -> 5000 | I5: ='Nov 2026'!D6+'Nov 2026'!H6 -> 5000 | J5: ='Dec 2026'!D6+'Dec 2026'!H6 -> 5000 | K5: =IFERROR(AVERAGEIF(C5:J5,">0"),0) -> 4674.6088 | L5: =SUM(C5:J5) -> 37396.87
B6: Carry-Over from Prior Month | C6: ='May 2026'!D9 -> 109.97 | D6: ='Jun 2026'!D9 -> 153.26 | E6: ='Jul 2026'!D9 -> 1989.775 | F6: ='Aug 2026'!D9 -> 4823.25 | G6: ='Sep 2026'!D9 -> 8202.305 | H6: ='Oct 2026'!D9 -> 11835.36 | I6: ='Nov 2026'!D9 -> 15383.415 | J6: ='Dec 2026'!D9 -> 19016.47 | K6: =IFERROR(AVERAGEIF(C6:J6,">0"),0) -> 7689.2256 | L6: =SUM(C6:J6) -> 61513.805
B7: Total Available (incl. carry-over) | C7: ='May 2026'!H8 -> 4277.32 | D7: ='Jun 2026'!H8 -> 4112.36 | E7: ='Jul 2026'!H8 -> 6260.195 | F7: ='Aug 2026'!H8 -> 9823.25 | G7: ='Sep 2026'!H8 -> 13202.305 | H7: ='Oct 2026'!H8 -> 16835.36 | I7: ='Nov 2026'!H8 -> 20383.415 | J7: ='Dec 2026'!H8 -> 24016.47 | K7: =IFERROR(AVERAGEIF(C7:J7,">0"),0) -> 12363.834 | L7: =SUM(C7:J7) -> 98910.675
B9: 🧾 SPENDING (YOUR SHARE)
B10: Groceries | C10: ='May 2026'!D12 -> 267.61 | D10: ='Jun 2026'!D12 -> 90.37 | E10: ='Jul 2026'!D12 -> 0 | F10: ='Aug 2026'!D12 -> 0 | G10: ='Sep 2026'!D12 -> 0 | H10: ='Oct 2026'!D12 -> 0 | I10: ='Nov 2026'!D12 -> 0 | J10: ='Dec 2026'!D12 -> 0 | K10: =IFERROR(AVERAGEIF(C10:J10,">0"),0) -> 178.99 | L10: =SUM(C10:J10) -> 357.98 | M10: ='Dec 2026'!D12 -> 0
B11: Utilities | C11: ='May 2026'!D13 -> 21.185 | D11: ='Jun 2026'!D13 -> 120.625 | E11: ='Jul 2026'!D13 -> 20.625 | F11: ='Aug 2026'!D13 -> 105.625 | G11: ='Sep 2026'!D13 -> 20.625 | H11: ='Oct 2026'!D13 -> 105.625 | I11: ='Nov 2026'!D13 -> 20.625 | J11: ='Dec 2026'!D13 -> 105.625 | K11: =IFERROR(AVERAGEIF(C11:J11,">0"),0) -> 65.07 | L11: =SUM(C11:J11) -> 520.56 | M11: ='Dec 2026'!D13 -> 105.625
B12: Gas / Transport | C12: ='May 2026'!D14 -> 232.935 | D12: ='Jun 2026'!D14 -> 81.27 | E12: ='Jul 2026'!D14 -> 65 | F12: ='Aug 2026'!D14 -> 65 | G12: ='Sep 2026'!D14 -> 65 | H12: ='Oct 2026'!D14 -> 65 | I12: ='Nov 2026'!D14 -> 65 | J12: ='Dec 2026'!D14 -> 65 | K12: =IFERROR(AVERAGEIF(C12:J12,">0"),0) -> 88.025625 | L12: =SUM(C12:J12) -> 704.205 | M12: ='Dec 2026'!D14 -> 65
B13: Dining / Takeout | C13: ='May 2026'!D15 -> 583.64 | D13: ='Jun 2026'!D15 -> 115.05 | E13: ='Jul 2026'!D15 -> 0 | F13: ='Aug 2026'!D15 -> 0 | G13: ='Sep 2026'!D15 -> 0 | H13: ='Oct 2026'!D15 -> 0 | I13: ='Nov 2026'!D15 -> 0 | J13: ='Dec 2026'!D15 -> 0 | K13: =IFERROR(AVERAGEIF(C13:J13,">0"),0) -> 349.345 | L13: =SUM(C13:J13) -> 698.69 | M13: ='Dec 2026'!D15 -> 0
B14: Entertainment | C14: ='May 2026'!D16 -> 117 | D14: ='Jun 2026'!D16 -> 0 | E14: ='Jul 2026'!D16 -> 0 | F14: ='Aug 2026'!D16 -> 0 | G14: ='Sep 2026'!D16 -> 0 | H14: ='Oct 2026'!D16 -> 0 | I14: ='Nov 2026'!D16 -> 0 | J14: ='Dec 2026'!D16 -> 0 | K14: =IFERROR(AVERAGEIF(C14:J14,">0"),0) -> 117 | L14: =SUM(C14:J14) -> 117 | M14: ='Dec 2026'!D16 -> 0
B15: Health | C15: ='May 2026'!D17 -> 189.5 | D15: ='Jun 2026'!D17 -> 13 | E15: ='Jul 2026'!D17 -> 105 | F15: ='Aug 2026'!D17 -> 105 | G15: ='Sep 2026'!D17 -> 105 | H15: ='Oct 2026'!D17 -> 105 | I15: ='Nov 2026'!D17 -> 105 | J15: ='Dec 2026'!D17 -> 105 | K15: =IFERROR(AVERAGEIF(C15:J15,">0"),0) -> 104.0625 | L15: =SUM(C15:J15) -> 832.5 | M15: ='Dec 2026'!D17 -> 105
B16: Shopping | C16: ='May 2026'!D18 -> 222.9125 | D16: ='Jun 2026'!D18 -> 0 | E16: ='Jul 2026'!D18 -> 0 | F16: ='Aug 2026'!D18 -> 0 | G16: ='Sep 2026'!D18 -> 0 | H16: ='Oct 2026'!D18 -> 0 | I16: ='Nov 2026'!D18 -> 0 | J16: ='Dec 2026'!D18 -> 0 | K16: =IFERROR(AVERAGEIF(C16:J16,">0"),0) -> 222.9125 | L16: =SUM(C16:J16) -> 222.9125 | M16: ='Dec 2026'!D18 -> 0
B17: Subscriptions | C17: ='May 2026'!D19 -> 71.57 | D17: ='Jun 2026'!D19 -> 71.57 | E17: ='Jul 2026'!D19 -> 65.62 | F17: ='Aug 2026'!D19 -> 65.62 | G17: ='Sep 2026'!D19 -> 65.62 | H17: ='Oct 2026'!D19 -> 65.62 | I17: ='Nov 2026'!D19 -> 65.62 | J17: ='Dec 2026'!D19 -> 65.62 | K17: =IFERROR(AVERAGEIF(C17:J17,">0"),0) -> 67.1075 | L17: =SUM(C17:J17) -> 536.86 | M17: ='Dec 2026'!D19 -> 65.62
B18: Cash | C18: ='May 2026'!D20 -> 140 | D18: ='Jun 2026'!D20 -> 0 | E18: ='Jul 2026'!D20 -> 0 | F18: ='Aug 2026'!D20 -> 0 | G18: ='Sep 2026'!D20 -> 0 | H18: ='Oct 2026'!D20 -> 0 | I18: ='Nov 2026'!D20 -> 0 | J18: ='Dec 2026'!D20 -> 0 | K18: =IFERROR(AVERAGEIF(C18:J18,">0"),0) -> 140 | L18: =SUM(C18:J18) -> 140 | M18: ='Dec 2026'!D20 -> 0
B19: Personal / Misc | C19: ='May 2026'!D21 -> 11.75 | D19: ='Jun 2026'!D21 -> 40 | E19: ='Jul 2026'!D21 -> 0 | F19: ='Aug 2026'!D21 -> 0 | G19: ='Sep 2026'!D21 -> 0 | H19: ='Oct 2026'!D21 -> 0 | I19: ='Nov 2026'!D21 -> 0 | J19: ='Dec 2026'!D21 -> 0 | K19: =IFERROR(AVERAGEIF(C19:J19,">0"),0) -> 25.875 | L19: =SUM(C19:J19) -> 51.75 | M19: ='Dec 2026'!D21 -> 0
B20: Other | C20: ='May 2026'!D22 -> 0 | D20: ='Jun 2026'!D22 -> 179.99 | E20: ='Jul 2026'!D22 -> 70 | F20: ='Aug 2026'!D22 -> 169 | G20: ='Sep 2026'!D22 -> 0 | H20: ='Oct 2026'!D22 -> 0 | I20: ='Nov 2026'!D22 -> 0 | J20: ='Dec 2026'!D22 -> 0 | K20: =IFERROR(AVERAGEIF(C20:J20,">0"),0) -> 139.66333 | L20: =SUM(C20:J20) -> 418.99 | M20: ='Dec 2026'!D22 -> 0
B21: Travel | C21: ='May 2026'!D23 -> 334.69 | D21: ='Jun 2026'!D23 -> 0 | E21: ='Jul 2026'!D23 -> 0 | F21: ='Aug 2026'!D23 -> 0 | G21: ='Sep 2026'!D23 -> 0 | H21: ='Oct 2026'!D23 -> 0 | I21: ='Nov 2026'!D23 -> 0 | J21: ='Dec 2026'!D23 -> 0 | K21: =IFERROR(AVERAGEIF(C21:J21,">0"),0) -> 334.69 | L21: =SUM(C21:J21) -> 334.69 | M21: ='Dec 2026'!D23 -> 0
B22: Investment (excl. Ally) | C22: ='May 2026'!D61 -> 867.78 | D22: ='Jun 2026'!D60 -> 1013.285 | E22: ='Jul 2026'!D60 -> 1090.075 | F22: ='Aug 2026'!D60 -> 1175.075 | G22: ='Sep 2026'!D60 -> 1090.075 | H22: ='Oct 2026'!D60 -> 1175.075 | I22: ='Nov 2026'!D60 -> 1090.075 | J22: ='Dec 2026'!D60 -> 1175.075 | K22: =SUM(C22:J22) -> 8676.515 | L22: =IFERROR(AVERAGEIF(C22:J22,">0"),0) -> 1084.5644 | M22: ='Dec 2026'!D61
B23: TOTAL GOING OUT | C23: ='May 2026'!D63 -> 800 | D23: ='Jun 2026'!D63 -> 300 | E23: ='Jul 2026'!D63 -> 0 | F23: ='Aug 2026'!D63 -> 0 | G23: ='Sep 2026'!D63 -> 0 | H23: ='Oct 2026'!D63 -> 0 | I23: ='Nov 2026'!D63 -> 0 | J23: ='Dec 2026'!D63 -> 0 | K23: =IFERROR(AVERAGEIF(C23:J23,">0"),0) -> 550 | L23: =SUM(C23:J23) -> 1100 | M23: ='Dec 2026'!D63 -> 0
B24: 💵 MONEY LEFT OVER | C24: ='May 2026'!D65 -> 153.26 | D24: ='Jun 2026'!D65 -> 1989.775 | E24: ='Jul 2026'!D65 -> 4823.25 | F24: ='Aug 2026'!D65 -> 8202.305 | G24: ='Sep 2026'!D65 -> 11835.36 | H24: ='Oct 2026'!D65 -> 15383.415 | I24: ='Nov 2026'!D65 -> 19016.47 | J24: ='Dec 2026'!D65 -> 22564.525 | K24: =IFERROR(AVERAGEIF(C24:J24,">0"),0) -> 10496.045 | L24: =SUM(C24:J24) -> 83968.36 | M24: ='Dec 2026'!D64 -> 1451.945
C25: ='May 2026'!D65 -> 153.26 | D25: ='Jun 2026'!D65 -> 1989.775 | E25: ='Jul 2026'!D65 -> 4823.25 | F25: ='Aug 2026'!D65 -> 8202.305 | G25: ='Sep 2026'!D65 -> 11835.36 | H25: ='Oct 2026'!D65 -> 15383.415 | I25: ='Nov 2026'!D65 -> 19016.47 | J25: ='Dec 2026'!D65 -> 22564.525 | K25: =IFERROR(AVERAGEIF(C25:J25,">0"),0) -> 10496.045 | L25: =SUM(C25:J25) -> 83968.36 | M25: ='Dec 2026'!D65 -> 22564.525
B26: 💳 CREDIT CARD CHARGES
B27: CFF | C27: ='May 2026'!D30 -> 94.11 | D27: ='Jun 2026'!D30 -> 54.98 | E27: ='Jul 2026'!D30 -> 15.98 | F27: ='Aug 2026'!D30 -> 15.98 | G27: ='Sep 2026'!D30 -> 15.98 | H27: ='Oct 2026'!D30 -> 15.98 | I27: ='Nov 2026'!D30 -> 15.98 | J27: ='Dec 2026'!D30 -> 15.98 | K27: =IFERROR(AVERAGEIF(C27:J27,">0"),0) -> 30.62125 | L27: =IFERROR(AVERAGEIF(C27:J27,">0"),0) -> 30.62125
B28: CFU | C28: ='May 2026'!D31 -> 0 | D28: ='Jun 2026'!D31 -> 0 | E28: ='Jul 2026'!D31 -> 0 | F28: ='Aug 2026'!D31 -> 0 | G28: ='Sep 2026'!D31 -> 0 | H28: ='Oct 2026'!D31 -> 0 | I28: ='Nov 2026'!D31 -> 0 | J28: ='Dec 2026'!D31 -> 0 | K28: =IFERROR(AVERAGEIF(C28:J28,">0"),0) -> 0 | L28: =IFERROR(AVERAGEIF(C28:J28,">0"),0) -> 0
B29: CSP | C29: ='May 2026'!D32 -> 0 | D29: ='Jun 2026'!D32 -> 0 | E29: ='Jul 2026'!D32 -> 0 | F29: ='Aug 2026'!D32 -> 0 | G29: ='Sep 2026'!D32 -> 0 | H29: ='Oct 2026'!D32 -> 0 | I29: ='Nov 2026'!D32 -> 0 | J29: ='Dec 2026'!D32 -> 0 | K29: =IFERROR(AVERAGEIF(C29:J29,">0"),0) -> 0 | L29: =IFERROR(AVERAGEIF(C29:J29,">0"),0) -> 0
B30: Discover | C30: ='May 2026'!D33 -> 736.26 | D30: ='Jun 2026'!D33 -> 77.35 | E30: ='Jul 2026'!D33 -> 41.25 | F30: ='Aug 2026'!D33 -> 41.25 | G30: ='Sep 2026'!D33 -> 41.25 | H30: ='Oct 2026'!D33 -> 41.25 | I30: ='Nov 2026'!D33 -> 41.25 | J30: ='Dec 2026'!D33 -> 41.25 | K30: =IFERROR(AVERAGEIF(C30:J30,">0"),0) -> 132.63875 | L30: =IFERROR(AVERAGEIF(C30:J30,">0"),0) -> 132.63875
B31: Citi | C31: ='May 2026'!D34 -> 178.04 | D31: ='Jun 2026'!D34 -> 32.54 | E31: ='Jul 2026'!D34 -> 0 | F31: ='Aug 2026'!D34 -> 0 | G31: ='Sep 2026'!D34 -> 0 | H31: ='Oct 2026'!D34 -> 0 | I31: ='Nov 2026'!D34 -> 0 | J31: ='Dec 2026'!D34 -> 0 | K31: =IFERROR(AVERAGEIF(C31:J31,">0"),0) -> 105.29 | L31: =IFERROR(AVERAGEIF(C31:J31,">0"),0) -> 105.29
B32: Capital One | C32: ='May 2026'!D35 -> 231.88 | D32: ='Jun 2026'!D35 -> 85.56 | E32: ='Jul 2026'!D35 -> 21.99 | F32: ='Aug 2026'!D35 -> 21.99 | G32: ='Sep 2026'!D35 -> 21.99 | H32: ='Oct 2026'!D35 -> 21.99 | I32: ='Nov 2026'!D35 -> 21.99 | J32: ='Dec 2026'!D35 -> 21.99 | K32: =IFERROR(AVERAGEIF(C32:J32,">0"),0) -> 56.1725 | L32: =IFERROR(AVERAGEIF(C32:J32,">0"),0) -> 56.1725
B33: WF | C33: ='May 2026'!D36 -> 11.75 | D33: ='Jun 2026'!D36 -> 0 | E33: ='Jul 2026'!D36 -> 0 | F33: ='Aug 2026'!D36 -> 0 | G33: ='Sep 2026'!D36 -> 0 | H33: ='Oct 2026'!D36 -> 0 | I33: ='Nov 2026'!D36 -> 0 | J33: ='Dec 2026'!D36 -> 0 | K33: =IFERROR(AVERAGEIF(C33:J33,">0"),0) -> 11.75 | L33: =IFERROR(AVERAGEIF(C33:J33,">0"),0) -> 11.75
B34: Amazon Card | C34: ='May 2026'!D37 -> 7.65 | D34: ='Jun 2026'!D37 -> 7.65 | E34: ='Jul 2026'!D37 -> 7.65 | F34: ='Aug 2026'!D37 -> 7.65 | G34: ='Sep 2026'!D37 -> 7.65 | H34: ='Oct 2026'!D37 -> 7.65 | I34: ='Nov 2026'!D37 -> 7.65 | J34: ='Dec 2026'!D37 -> 7.65 | K34: =IFERROR(AVERAGEIF(C34:J34,">0"),0) -> 7.65 | L34: =IFERROR(AVERAGEIF(C34:J34,">0"),0) -> 7.65
B35: Robinhood | C35: ='May 2026'!D38 -> 991.59 | D35: ='Jun 2026'!D38 -> 446.22 | E35: ='Jul 2026'!D38 -> 195 | F35: ='Aug 2026'!D38 -> 294 | G35: ='Sep 2026'!D38 -> 125 | H35: ='Oct 2026'!D38 -> 125 | I35: ='Nov 2026'!D38 -> 125 | J35: ='Dec 2026'!D38 -> 125 | K35: =IFERROR(AVERAGEIF(C35:J35,">0"),0) -> 303.35125 | L35: =IFERROR(AVERAGEIF(C35:J35,">0"),0) -> 303.35125
B36: Cash | C36: ='May 2026'!D39 -> 205 | D36: ='Jun 2026'!D39 -> 105 | E36: ='Jul 2026'!D39 -> 65 | F36: ='Aug 2026'!D39 -> 65 | G36: ='Sep 2026'!D39 -> 65 | H36: ='Oct 2026'!D39 -> 65 | I36: ='Nov 2026'!D39 -> 65 | J36: ='Dec 2026'!D39 -> 65 | K36: =IFERROR(AVERAGEIF(C36:J36,">0"),0) -> 87.5 | L36: =IFERROR(AVERAGEIF(C36:J36,">0"),0) -> 87.5
B37: Other | C37: ='May 2026'!D40 -> 0 | D37: ='Jun 2026'!D40 -> 0 | E37: ='Jul 2026'!D40 -> 0 | F37: ='Aug 2026'!D40 -> 0 | G37: ='Sep 2026'!D40 -> 0 | H37: ='Oct 2026'!D40 -> 0 | I37: ='Nov 2026'!D40 -> 0 | J37: ='Dec 2026'!D40 -> 0 | K37: =IFERROR(AVERAGEIF(C37:J37,">0"),0) -> 0 | L37: =IFERROR(AVERAGEIF(C37:J37,">0"),0) -> 0
B38: TOTAL CC CHARGES | C38: ='May 2026'!D41 -> 2456.28 | D38: ='Jun 2026'!D41 -> 809.3 | E38: ='Jul 2026'!D41 -> 346.87 | F38: ='Aug 2026'!D41 -> 445.87 | G38: ='Sep 2026'!D41 -> 276.87 | H38: ='Oct 2026'!D41 -> 276.87 | I38: ='Nov 2026'!D41 -> 276.87 | J38: ='Dec 2026'!D41 -> 276.87 | K38: =SUM(C38:J38) -> 5165.8 | L38: =IFERROR(AVERAGEIF(C38:J38,">0"),0) -> 645.725
B40: 📈 INVESTMENTS & SAVINGS
B41: Robinhood — Added | C41: ='May 2026'!D45 -> 300 | D41: ='Jun 2026'!D45 -> 300 | E41: ='Jul 2026'!D45 -> 0 | F41: ='Aug 2026'!D45 -> 0 | G41: ='Sep 2026'!D45 -> 0 | H41: ='Oct 2026'!D45 -> 0 | I41: ='Nov 2026'!D45 -> 0 | J41: ='Dec 2026'!D45 -> 0 | K41: =IFERROR(AVERAGEIF(C41:J41,">0"),0) -> 300 | L41: =IFERROR(AVERAGEIF(C41:J41,">0"),0) -> 300
B42: Vanguard IRA — Added | C42: ='May 2026'!D46 -> 500 | D42: ='Jun 2026'!D46 -> 0 | E42: ='Jul 2026'!D46 -> 0 | F42: ='Aug 2026'!D46 -> 0 | G42: ='Sep 2026'!D46 -> 0 | H42: ='Oct 2026'!D46 -> 0 | I42: ='Nov 2026'!D46 -> 0 | J42: ='Dec 2026'!D46 -> 0 | K42: =IFERROR(AVERAGEIF(C42:J42,">0"),0) -> 500 | L42: =IFERROR(AVERAGEIF(C42:J42,">0"),0) -> 500
...

Sheet May 2026
B2: 💰 May 2026 — Expense Tracker
B3: LEFT: summaries auto-update | RIGHT: log every transaction | Blue cells = enter data
B5: ⚙️ SETTINGS
B6: Paycheck #1 (mid-mo) | D6: 2135.21 | F6: Paycheck #2 (end-mo) | H6: 2032.14
B7: Full Monthly Rent | D7: 2221.4 | F7: Your Rent Split % | H7: 0.5
B8: Monthly Savings Goal | D8: 500 | F8: Total Monthly Income | H8: =D6+H6+D9 -> 4277.32
B9: Carried Over (prior month) | D9: 109.97
B10: 📊 CATEGORY SUMMARY | J10: 📋 EXPENSE LOG — Enter every transaction here
B11: Category | D11: Your Share $ | E11: % Income | F11: Budget $ | G11: vs Budget | J11: # | K11: Date | L11: Description | M11: Category | N11: Credit Card | O11: Total $ | P11: Split % | Q11: Your Share $ | R11: Notes / Memo | S11: Recurring?
B12: Groceries | D12: =SUMIF(M12:M131,B12,Q12:Q131) -> 267.61 | E12: =IFERROR(D12/(H8),0) -> 0.062564877 | F12: 300 | G12: =IF(D12=0,"",D12-F12) -> -32.39 | J12: 1 | K12: 46143 | L12: Car Insurance | M12: Gas / Transport | N12: Cash | O12: 65 | P12: 1 | Q12: =IFERROR(IF(O12="",0,O12*P12),0) -> 65 | R12: Auto-pay | S12: Y
B13: Utilities | D13: =SUMIF(M12:M131,B13,Q12:Q131) -> 21.185 | E13: =IFERROR(D13/(H8),0) -> 0.0049528677 | F13: 50 | G13: =IF(D13=0,"",D13-F13) -> -28.815 | J13: 2 | K13: 46143 | L13: Stronghold | M13: Health | N13: Robinhood | O13: 105 | P13: 1 | Q13: =IFERROR(IF(O13="",0,O13*P13),0) -> 105 | R13: Auto-pay | S13: Y
B14: Gas / Transport | D14: =SUMIF(M12:M131,B14,Q12:Q131) -> 232.935 | E14: =IFERROR(D14/(H8),0) -> 0.054458165 | F14: 250 | G14: =IF(D14=0,"",D14-F14) -> -17.065 | J14: 3 | K14: 46143 | L14: Spectrum Internet | M14: Utilities | N14: Discover | O14: 41.25 | P14: 0.5 | Q14: =IFERROR(IF(O14="",0,O14*P14),0) -> 20.625 | R14: Auto-pay | S14: Y
B15: Dining / Takeout | D15: =SUMIF(M12:M131,B15,Q12:Q131) -> 583.64 | E15: =IFERROR(D15/(H8),0) -> 0.13644993 | F15: 300 | G15: =IF(D15=0,"",D15-F15) -> 283.64 | J15: 4 | K15: 46143 | L15: Amazon Prime | M15: Subscriptions | N15: Amazon Card | O15: 7.65 | P15: 1 | Q15: =IFERROR(IF(O15="",0,O15*P15),0) -> 7.65 | R15: Auto-pay | S15: Y
B16: Entertainment | D16: =SUMIF(M12:M131,B16,Q12:Q131) -> 117 | E16: =IFERROR(D16/(H8),0) -> 0.027353577 | F16: 150 | G16: =IF(D16=0,"",D16-F16) -> -33 | J16: 5 | K16: 46143 | L16: Spotify | M16: Subscriptions | N16: Capital One | O16: 21.99 | P16: 1 | Q16: =IFERROR(IF(O16="",0,O16*P16),0) -> 21.99 | R16: Auto-pay | S16: Y
B17: Health | D17: =SUMIF(M12:M131,B17,Q12:Q131) -> 189.5 | E17: =IFERROR(D17/(H8),0) -> 0.044303442 | F17: 200 | G17: =IF(D17=0,"",D17-F17) -> -10.5 | J17: 6 | K17: 46143 | L17: Electricity | M17: Utilities | P17: 0.5 | Q17: =IFERROR(IF(O17="",0,O17*P17),0) -> 0 | R17: She pays | S17: Y
B18: Shopping | D18: =SUMIF(M12:M131,B18,Q12:Q131) -> 222.9125 | E18: =IFERROR(D18/(H8),0) -> 0.052114993 | F18: 200 | G18: =IF(D18=0,"",D18-F18) -> 22.9125 | J18: 7 | K18: 46143 | L18: Twitch Sub | M18: Subscriptions | N18: CFF | O18: 5.99 | P18: 1 | Q18: =IFERROR(IF(O18="",0,O18*P18),0) -> 5.99 | R18: Auto-pay | S18: Y
B19: Subscriptions | D19: =SUMIF(M12:M131,B19,Q12:Q131) -> 71.57 | E19: =IFERROR(D19/(H8),0) -> 0.01673244 | F19: 100 | G19: =IF(D19=0,"",D19-F19) -> -28.43 | J19: 8 | K19: 46143 | L19: Claude AI | M19: Subscriptions | N19: Robinhood | O19: 20 | P19: 1 | Q19: =IFERROR(IF(O19="",0,O19*P19),0) -> 20 | R19: Auto-pay | S19: Y
B20: Cash | D20: =SUMIF(M12:M131,B20,Q12:Q131) -> 140 | E20: =IFERROR(D20/(H8),0) -> 0.032730775 | F20: 150 | G20: =IF(D20=0,"",D20-F20) -> -10 | J20: 9 | K20: 46143 | L20: Discord | M20: Subscriptions | N20: CFF | O20: 9.99 | P20: 1 | Q20: =IFERROR(IF(O20="",0,O20*P20),0) -> 9.99 | R20: Auto-pay | S20: Y
B21: Personal / Misc | D21: =SUMIF(M12:M131,B21,Q12:Q131) -> 11.75 | E21: =IFERROR(D21/(H8),0) -> 0.0027470472 | F21: 50 | G21: =IF(D21=0,"",D21-F21) -> -38.25 | J21: 10 | K21: 46143 | L21: Ervin Gas | M21: Gas / Transport | N21: Citi | O21: 65.59 | P21: 1 | Q21: =IFERROR(IF(O21="",0,O21*P21),0) -> 65.59
B22: Other | D22: =SUMIF(M12:M131,B22,Q12:Q131) -> 0 | E22: =IFERROR(D22/(H8),0) -> 0 | F22: 350 | G22: =IF(D22=0,"",D22-F22) | J22: 11 | K22: 46148 | L22: Sharon Gas | M22: Gas / Transport | N22: Citi | O22: 27.47 | P22: 0.5 | Q22: =IFERROR(IF(O22="",0,O22*P22),0) -> 13.735
B23: Travel | D23: =SUMIF($M$12:$M$131,B23,$Q$12:$Q$131) -> 334.69 | E23: =IFERROR(D23/(H8),0) -> 0.078247594 | F23: 150 | G23: =IF(D23=0,"",D23-F23) -> 184.69 | J23: 12 | K23: 46144 | L23: Ralphs 1 | M23: Groceries | N23: CFF | O23: 23.95 | P23: 0.5 | Q23: =IFERROR(IF(O23="",0,O23*P23),0) -> 11.975
B24: Adjusted Rent | D24: =D61 -> 867.78 | E24: =IFERROR(D24/(H8),0) -> 0.20287937 | J24: 13 | K24: 46144 | L24: Costco | M24: Groceries | N24: Robinhood | O24: 76.07 | P24: 0.5 | Q24: =IFERROR(IF(O24="",0,O24*P24),0) -> 38.035
B25: Investment | D25: =D63 -> 800 | E25: =IFERROR(D25/(H8),0) -> 0.187033 | J25: 14 | K25: 46148 | L25: Albertsons | M25: Groceries | N25: Capital One | O25: 15.26 | P25: 0.5 | Q25: =IFERROR(IF(O25="",0,O25*P25),0) -> 7.63
B26: TOTAL Going Out | D26: =D64 -> 4124.06 | E26: =IFERROR(D26/(H8),0) -> 0.96416915 | J26: 15 | K26: 46151 | L26: TJs | M26: Groceries | O26: 13.96 | P26: 0.5 | Q26: =IFERROR(IF(O26="",0,O26*P26),0) -> 6.98
B27: 💵 Money Left Over | D27: =D65 -> 153.26 | E27: =IFERROR(D27/(H8),0) -> 0.035830847 | J27: 16 | K27: 46154 | L27: Costco + Ralph's | M27: Groceries | N27: Robinhood | O27: 51.3 | P27: 0.5 | Q27: =IFERROR(IF(O27="",0,O27*P27),0) -> 25.65
J28: 17 | K28: 46154 | L28: Stater Bros | M28: Groceries | N28: Capital One | O28: 6.98 | P28: 0.5 | Q28: =IFERROR(IF(O28="",0,O28*P28),0) -> 3.49
B29: Card | D29: Total This Month $ | J29: 18 | K29: 46152 | L29: Jons | M29: Groceries | O29: 10.77 | P29: 0.5 | Q29: =IFERROR(IF(O29="",0,O29*P29),0) -> 5.385
B30: CFF | D30: =SUMIF(N12:N131,B30,O12:O131) -> 94.11 | J30: 19 | K30: 46154 | L30: Target | M30: Groceries | N30: Robinhood | O30: 13.81 | P30: 0.5 | Q30: =IFERROR(IF(O30="",0,O30*P30),0) -> 6.905
B31: CFU | D31: =SUMIF(N12:N131,B31,O12:O131) -> 0 | J31: 20 | K31: 46155 | L31: Grocery Outlet | M31: Groceries | N31: Capital One | O31: 9.25 | P31: 0.5 | Q31: =IFERROR(IF(O31="",0,O31*P31),0) -> 4.625
B32: CSP | D32: =SUMIF(N12:N131,B32,O12:O131) -> 0 | J32: 21 | K32: 46144 | L32: Tacos Ervin | M32: Dining / Takeout | N32: Discover | O32: 59.19 | P32: 0.5 | Q32: =IFERROR(IF(O32="",0,O32*P32),0) -> 29.595
B33: Discover | D33: =SUMIF(N12:N131,B33,O12:O131) -> 736.26 | J33: 22 | K33: 46144 | L33: Tacos and proof Sharon | M33: Dining / Takeout | O33: =(5+11.21+6+13) -> 35.21 | P33: 0.5 | Q33: =IFERROR(IF(O33="",0,O33*P33),0) -> 17.605
B34: Citi | D34: =SUMIF(N12:N131,B34,O12:O131) -> 178.04 | J34: 23 | K34: 46147 | L34: Izakaya | M34: Dining / Takeout | N34: Discover | O34: 100.32 | P34: 0.5 | Q34: =IFERROR(IF(O34="",0,O34*P34),0) -> 50.16
B35: Capital One | D35: =SUMIF(N12:N131,B35,O12:O131) -> 231.88 | J35: 24 | K35: 46149 | L35: Paris baguette | M35: Dining / Takeout | N35: Discover | O35: 12.8 | P35: 1 | Q35: =IFERROR(IF(O35="",0,O35*P35),0) -> 12.8
B36: WF | D36: =SUMIF(N12:N131,B36,O12:O131) -> 11.75 | J36: 25 | K36: 46150 | L36: Dominoes | M36: Dining / Takeout | N36: Discover | O36: 13.17 | P36: 0.5 | Q36: =IFERROR(IF(O36="",0,O36*P36),0) -> 6.585
B37: Amazon Card | D37: =SUMIF(N12:N131,B37,O12:O131) -> 7.65 | J37: 26 | K37: 46150 | L37: Chilis | M37: Dining / Takeout | N37: Discover | O37: 52 | P37: 0.5 | Q37: =IFERROR(IF(O37="",0,O37*P37),0) -> 26
B38: Robinhood | D38: =SUMIF(N12:N131,B38,O12:O131) -> 991.59 | J38: 27 | K38: 46151 | L38: Toontown market foods | M38: Dining / Takeout | N38: Discover | O38: 36.55 | P38: 0.5 | Q38: =IFERROR(IF(O38="",0,O38*P38),0) -> 18.275
B39: Cash | D39: =SUMIF(N12:N131,B39,O12:O131) -> 205 | J39: 28 | K39: 46151 | L39: Smoke queen | M39: Dining / Takeout | N39: Discover | O39: 107.87 | P39: 0.5 | Q39: =IFERROR(IF(O39="",0,O39*P39),0) -> 53.935
B40: Other | D40: =SUMIF(N12:N131,B40,O12:O131) -> 0 | J40: 29 | K40: 46152 | L40: Coffee Disney | M40: Dining / Takeout | N40: Discover | O40: 8.25 | P40: 1 | Q40: =IFERROR(IF(O40="",0,O40*P40),0) -> 8.25
B41: TOTAL CC CHARGES | D41: =SUM(D30:D40) -> 2456.28 | J41: 30 | K41: 46152 | L41: Sundae churros | M41: Dining / Takeout | N41: Discover | O41: 12.16 | P41: 0.5 | Q41: =IFERROR(IF(O41="",0,O41*P41),0) -> 6.08
J42: 31 | K42: 46152 | L42: Chicken Bao | M42: Dining / Takeout | O42: 16.15 | P42: 0.5 | Q42: =IFERROR(IF(O42="",0,O42*P42),0) -> 8.075
...

Sheet Jun 2026
B2: 💰 Jun 2026 — Expense Tracker
B3: LEFT: summaries auto-update | RIGHT: log every transaction | Blue cells = enter data
B5: ⚙️ SETTINGS
B6: Paycheck #1 (mid-mo) | D6: 1926.96 | F6: Paycheck #2 (end-mo) | H6: 2032.14
B7: Full Monthly Rent | D7: 2221.4 | F7: Your Rent Split % | H7: 0.5
B8: Monthly Savings Goal | D8: 500 | F8: Total Monthly Income | H8: =D6+H6+D9 -> 4112.36
B9: Carried Over (prior month) | D9: ='May 2026'!D65 -> 153.26
B10: 📊 CATEGORY SUMMARY | J10: 📋 EXPENSE LOG — Enter every transaction here
B11: Category | D11: Your Share $ | E11: % Income | F11: Budget $ | G11: vs Budget | J11: # | K11: Date | L11: Description | M11: Category | N11: Credit Card | O11: Total $ | P11: Split % | Q11: Your Share $ | R11: Notes / Memo | S11: Recurring?
B12: Groceries | D12: =SUMIF(M12:M131,B12,Q12:Q131) -> 90.37 | E12: =IFERROR(D12/(H8),0) -> 0.021975216 | F12: 300 | G12: =IF(D12=0,"",D12-F12) -> -209.63 | J12: 1 | K12: 46174 | L12: Car Insurance | M12: Gas / Transport | N12: Cash | O12: 65 | P12: 1 | Q12: =IFERROR(IF(O12="",0,O12*P12),0) -> 65 | R12: Auto-pay | S12: Y
B13: Utilities | D13: =SUMIF(M12:M131,B13,Q12:Q131) -> 120.625 | E13: =IFERROR(D13/(H8),0) -> 0.029332306 | F13: 150 | G13: =IF(D13=0,"",D13-F13) -> -29.375 | J13: 2 | K13: 46174 | L13: Stronghold | M13: Health | N13: Robinhood | O13: 13 | P13: 1 | Q13: 13 | R13: Auto-pay
B14: Gas / Transport | D14: =SUMIF(M12:M131,B14,Q12:Q131) -> 81.27 | E14: =IFERROR(D14/(H8),0) -> 0.019762375 | F14: 200 | G14: =IF(D14=0,"",D14-F14) -> -118.73 | J14: 3 | K14: 46174 | L14: Spectrum Internet | M14: Utilities | N14: Discover | O14: 41.25 | P14: 0.5 | Q14: =IFERROR(IF(O14="",0,O14*P14),0) -> 20.625 | R14: Auto-pay | S14: Y
B15: Dining / Takeout | D15: =SUMIF(M12:M131,B15,Q12:Q131) -> 115.05 | E15: =IFERROR(D15/(H8),0) -> 0.027976636 | F15: 300 | G15: =IF(D15=0,"",D15-F15) -> -184.95 | J15: 4 | K15: 46174 | L15: Amazon Prime | M15: Subscriptions | N15: Amazon Card | O15: 7.65 | P15: 1 | Q15: =IFERROR(IF(O15="",0,O15*P15),0) -> 7.65 | R15: Auto-pay | S15: Y
B16: Entertainment | D16: =SUMIF(M12:M131,B16,Q12:Q131) -> 0 | E16: =IFERROR(D16/(H8),0) -> 0 | F16: 150 | G16: =IF(D16=0,"",D16-F16) | J16: 5 | K16: 46174 | L16: Spotify | M16: Subscriptions | N16: Capital One | O16: 21.99 | P16: 1 | Q16: =IFERROR(IF(O16="",0,O16*P16),0) -> 21.99 | R16: Auto-pay | S16: Y
B17: Health | D17: =SUMIF(M12:M131,B17,Q12:Q131) -> 13 | E17: =IFERROR(D17/(H8),0) -> 0.0031612018 | F17: 200 | G17: =IF(D17=0,"",D17-F17) -> -187 | J17: 6 | K17: 46174 | L17: Electricity | M17: Utilities | O17: 170 | P17: 0.5 | Q17: =IFERROR(IF(O17="",0,O17*P17),0) -> 85 | R17: She pays | S17: Y
B18: Shopping | D18: =SUMIF(M12:M131,B18,Q12:Q131) -> 0 | E18: =IFERROR(D18/(H8),0) -> 0 | F18: 200 | G18: =IF(D18=0,"",D18-F18) | J18: 7 | K18: 46174 | L18: Twitch Sub | M18: Subscriptions | N18: CFF | O18: 5.99 | P18: 1 | Q18: =IFERROR(IF(O18="",0,O18*P18),0) -> 5.99 | R18: Auto-pay | S18: Y
B19: Subscriptions | D19: =SUMIF(M12:M131,B19,Q12:Q131) -> 71.57 | E19: =IFERROR(D19/(H8),0) -> 0.017403632 | F19: 100 | G19: =IF(D19=0,"",D19-F19) -> -28.43 | J19: 8 | K19: 46174 | L19: Claude AI | M19: Subscriptions | N19: Robinhood | O19: 20 | P19: 1 | Q19: =IFERROR(IF(O19="",0,O19*P19),0) -> 20 | R19: Auto-pay | S19: Y
B20: Cash | D20: =SUMIF(M12:M131,B20,Q12:Q131) -> 0 | E20: =IFERROR(D20/(H8),0) -> 0 | F20: 100 | G20: =IF(D20=0,"",D20-F20) | J20: 9 | K20: 46174 | L20: Discord | M20: Subscriptions | N20: CFF | O20: 9.99 | P20: 1 | Q20: =IFERROR(IF(O20="",0,O20*P20),0) -> 9.99 | R20: Auto-pay | S20: Y
B21: Personal / Misc | D21: =SUMIF(M12:M131,B21,Q12:Q131) -> 40 | E21: =IFERROR(D21/(H8),0) -> 0.0097267749 | F21: 50 | G21: =IF(D21=0,"",D21-F21) -> -10 | J21: 10 | K21: 46175 | L21: Laundromat | M21: Utilities | N21: Robinhood | O21: 15 | P21: 1 | Q21: 15
B22: Other | D22: =SUMIF(M12:M131,B22,Q12:Q131) -> 179.99 | E22: =IFERROR(D22/(H8),0) -> 0.043768055 | F22: 700 | G22: =IF(D22=0,"",D22-F22) -> -520.01 | J22: 11 | K22: 46176 | L22: Sharon Gas 1 | M22: Gas / Transport | N22: Citi | O22: 32.54 | P22: 0.5 | Q22: 16.27
B23: Travel | D23: =SUMIF($M$12:$M$131,B23,$Q$12:$Q$131) -> 0 | E23: =IFERROR(D23/(H8),0) -> 0 | F23: 100 | G23: =IF(D23=0,"",D23-F23) | J23: 12 | K23: 46176 | L23: Max’s | M23: Dining / Takeout | O23: 32 | P23: 0.5 | Q23: =IFERROR(IF(O23="",0,O23*P23),0) -> 16
B24: Adjusted Rent | D24: =D60 -> 1013.285 | E24: =IFERROR(D24/(H8),0) -> 0.24639988 | J24: 13 | K24: 46174 | L24: Pa Ord noodles | M24: Dining / Takeout | O24: 24 | P24: 0.5 | Q24: 12
B25: Investment | D25: =D63 -> 300 | E25: =IFERROR(D25/(H8),0) -> 0.072950812 | J25: 14 | K25: 46185 | L25: Cash for Haircut | M25: Personal / Misc | N25: Cash | O25: 40 | P25: 1 | Q25: 40
B26: TOTAL Going Out | D26: =D64 -> 2122.585 | E26: =IFERROR(D26/(H8),0) -> 0.51614766 | J26: 15 | K26: 46175 | L26: LA TACO | M26: Subscriptions | N26: Robinhood | O26: 5.95 | P26: 1 | Q26: =IFERROR(IF(O26="",0,O26*P26),0) -> 5.95
B27: 💵 Money Left Over | D27: =D65 -> 1989.775 | E27: =IFERROR(D27/(H8),0) -> 0.48385234 | J27: 16 | K27: 46176 | L27: Birthday cake Whole Foods | M27: Dining / Takeout | N27: CFF | O27: 39 | P27: 1 | Q27: 39
J28: 17 | K28: 46178 | L28: DERA Crepe | M28: Dining / Takeout | N28: Discover | O28: 25.68 | P28: 1 | Q28: 25.68 | R28: For parents
B29: Card | D29: Total This Month $ | J29: 18 | K29: 46191 | L29: AAA Membership | M29: Other | N29: Robinhood | O29: 95 | P29: 1 | Q29: 95
B30: CFF | D30: =SUMIF(N12:N131,B30,O12:O131) -> 54.98 | J30: 19 | K30: 46179 | L30: Laundry 2 Sharon | M30: Utilities | N30: Robinhood | O30: 10 | P30: 0 | Q30: 0
B31: CFU | D31: =SUMIF(N12:N131,B31,O12:O131) -> 0 | J31: 20 | K31: 46180 | L31: New Airfryer! | M31: Other | N31: Robinhood | O31: 150 | P31: 0.5 | Q31: 75
B32: CSP | D32: =SUMIF(N12:N131,B32,O12:O131) -> 0 | J32: 21 | K32: 46180 | L32: Costco 1 | M32: Groceries | N32: Robinhood | O32: 113.22 | P32: 0.5 | Q32: 56.61
B33: Discover | D33: =SUMIF(N12:N131,B33,O12:O131) -> 77.35 | J33: 22 | K33: 46180 | L33: Ding Tea | M33: Dining / Takeout | N33: Robinhood | O33: 14.06 | P33: 0.85 | Q33: 11.95
B34: Citi | D34: =SUMIF(N12:N131,B34,O12:O131) -> 32.54 | J34: 23 | K34: 46181 | L34: Ralphs + chocolate milk | M34: Groceries | N34: Capital One | O34: 19.84 | P34: 0.6 | Q34: 11.9
B35: Capital One | D35: =SUMIF(N12:N131,B35,O12:O131) -> 85.56 | J35: 24 | K35: 46182 | L35: The Finals Video Game | M35: Other | N35: Robinhood | O35: 9.99 | P35: 1 | Q35: 9.99
B36: WF | D36: =SUMIF(N12:N131,B36,O12:O131) -> 0 | J36: 25 | K36: 46183 | L36: Pizza Hut | M36: Dining / Takeout | N36: Discover | O36: 10.42 | P36: 1 | Q36: 10.42
B37: Amazon Card | D37: =SUMIF(N12:N131,B37,O12:O131) -> 7.65 | J37: 26 | K37: 46183 | L37: Little Tokyo Market Place 1 | M37: Groceries | N37: Capital One | O37: 43.73 | P37: 0.5 | Q37: 21.86
B38: Robinhood | D38: =SUMIF(N12:N131,B38,O12:O131) -> 446.22 | J38: 27 | P38: 1 | Q38: =IFERROR(IF(O38="",0,O38*P38),0) -> 0
B39: Cash | D39: =SUMIF(N12:N131,B39,O12:O131) -> 105 | J39: 28 | P39: 1 | Q39: =IFERROR(IF(O39="",0,O39*P39),0) -> 0
B40: Other | D40: =SUMIF(N12:N131,B40,O12:O131) -> 0 | J40: 29 | P40: 1 | Q40: =IFERROR(IF(O40="",0,O40*P40),0) -> 0
B41: TOTAL CC CHARGES | D41: =SUM(D30:D40) -> 809.3 | J41: 30 | P41: 1 | Q41: =IFERROR(IF(O41="",0,O41*P41),0) -> 0
J42: 31 | P42: 1 | Q42: =IFERROR(IF(O42="",0,O42*P42),0) -> 0
...

Sheet Jul 2026
B2: 💰 Jul 2026 — Expense Tracker
B3: LEFT: summaries auto-update | RIGHT: log every transaction | Blue cells = enter data
B5: ⚙️ SETTINGS
B6: Paycheck #1 (mid-mo) | D6: 2135.21 | F6: Paycheck #2 (end-mo) | H6: 2135.21
B7: Full Monthly Rent | D7: 2221.4 | F7: Your Rent Split % | H7: 0.5
B8: Monthly Savings Goal | D8: 500 | F8: Total Monthly Income | H8: =D6+H6+D9 -> 6260.195
B9: Carried Over (prior month) | D9: ='Jun 2026'!D65 -> 1989.775
B10: 📊 CATEGORY SUMMARY | J10: 📋 EXPENSE LOG — Enter every transaction here
B11: Category | D11: Your Share $ | E11: % Income | F11: Budget $ | G11: vs Budget | J11: # | K11: Date | L11: Description | M11: Category | N11: Credit Card | O11: Total $ | P11: Split % | Q11: Your Share $ | R11: Notes / Memo | S11: Recurring?
B12: Groceries | D12: =SUMIF(M12:M131,B12,Q12:Q131) -> 0 | E12: =IFERROR(D12/(H8),0) -> 0 | F12: 300 | G12: =IF(D12=0,"",D12-F12) | J12: 1 | K12: 46204 | L12: Car Insurance | M12: Gas / Transport | N12: Cash | O12: 65 | P12: 1 | Q12: =IFERROR(IF(O12="",0,O12*P12),0) -> 65 | R12: Auto-pay | S12: Y
B13: Utilities | D13: =SUMIF(M12:M131,B13,Q12:Q131) -> 20.625 | E13: =IFERROR(D13/(H8),0) -> 0.0032946258 | F13: 50 | G13: =IF(D13=0,"",D13-F13) -> -29.375 | J13: 2 | K13: 46204 | L13: Stronghold | M13: Health | N13: Robinhood | O13: 105 | P13: 1 | Q13: =IFERROR(IF(O13="",0,O13*P13),0) -> 105 | R13: Auto-pay | S13: Y
B14: Gas / Transport | D14: =SUMIF(M12:M131,B14,Q12:Q131) -> 65 | E14: =IFERROR(D14/(H8),0) -> 0.010383063 | F14: 200 | G14: =IF(D14=0,"",D14-F14) -> -135 | J14: 3 | K14: 46204 | L14: Spectrum Internet | M14: Utilities | N14: Discover | O14: 41.25 | P14: 0.5 | Q14: =IFERROR(IF(O14="",0,O14*P14),0) -> 20.625 | R14: Auto-pay | S14: Y
B15: Dining / Takeout | D15: =SUMIF(M12:M131,B15,Q12:Q131) -> 0 | E15: =IFERROR(D15/(H8),0) -> 0 | F15: 300 | G15: =IF(D15=0,"",D15-F15) | J15: 4 | K15: 46204 | L15: Amazon Prime | M15: Subscriptions | N15: Amazon Card | O15: 7.65 | P15: 1 | Q15: =IFERROR(IF(O15="",0,O15*P15),0) -> 7.65 | R15: Auto-pay | S15: Y
B16: Entertainment | D16: =SUMIF(M12:M131,B16,Q12:Q131) -> 0 | E16: =IFERROR(D16/(H8),0) -> 0 | F16: 150 | G16: =IF(D16=0,"",D16-F16) | J16: 5 | K16: 46204 | L16: Spotify | M16: Subscriptions | N16: Capital One | O16: 21.99 | P16: 1 | Q16: =IFERROR(IF(O16="",0,O16*P16),0) -> 21.99 | R16: Auto-pay | S16: Y
B17: Health | D17: =SUMIF(M12:M131,B17,Q12:Q131) -> 105 | E17: =IFERROR(D17/(H8),0) -> 0.01677264 | F17: 200 | G17: =IF(D17=0,"",D17-F17) -> -95 | J17: 6 | K17: 46204 | L17: Electricity | M17: Utilities | P17: 0.5 | Q17: =IFERROR(IF(O17="",0,O17*P17),0) -> 0 | R17: She pays | S17: Y
B18: Shopping | D18: =SUMIF(M12:M131,B18,Q12:Q131) -> 0 | E18: =IFERROR(D18/(H8),0) -> 0 | F18: 200 | G18: =IF(D18=0,"",D18-F18) | J18: 7 | K18: 46204 | L18: Twitch Sub | M18: Subscriptions | N18: CFF | O18: 5.99 | P18: 1 | Q18: =IFERROR(IF(O18="",0,O18*P18),0) -> 5.99 | R18: Auto-pay | S18: Y
B19: Subscriptions | D19: =SUMIF(M12:M131,B19,Q12:Q131) -> 65.62 | E19: =IFERROR(D19/(H8),0) -> 0.010482102 | F19: 100 | G19: =IF(D19=0,"",D19-F19) -> -34.38 | J19: 8 | K19: 46204 | L19: Claude AI | M19: Subscriptions | N19: Robinhood | O19: 20 | P19: 1 | Q19: =IFERROR(IF(O19="",0,O19*P19),0) -> 20 | R19: Auto-pay | S19: Y
B20: Cash | D20: =SUMIF(M12:M131,B20,Q12:Q131) -> 0 | E20: =IFERROR(D20/(H8),0) -> 0 | F20: 100 | G20: =IF(D20=0,"",D20-F20) | J20: 9 | K20: 46204 | L20: Discord | M20: Subscriptions | N20: CFF | O20: 9.99 | P20: 1 | Q20: =IFERROR(IF(O20="",0,O20*P20),0) -> 9.99 | R20: Auto-pay | S20: Y
B21: Personal / Misc | D21: =SUMIF(M12:M131,B21,Q12:Q131) -> 0 | E21: =IFERROR(D21/(H8),0) -> 0 | F21: 50 | G21: =IF(D21=0,"",D21-F21) | J21: 10 | K21: 46213 | L21: SMOG | M21: Other | N21: Robinhood | O21: 70 | P21: 1 | Q21: 70 | S21: TRUE
B22: Other | D22: =SUMIF(M12:M131,B22,Q12:Q131) -> 70 | E22: =IFERROR(D22/(H8),0) -> 0.01118176 | F22: 300 | G22: =IF(D22=0,"",D22-F22) -> -230 | J22: 11 | P22: 1 | Q22: =IFERROR(IF(O22="",0,O22*P22),0) -> 0
B23: Travel | D23: =SUMIF($M$12:$M$131,B23,$Q$12:$Q$131) -> 0 | E23: =IFERROR(D23/(H8),0) -> 0 | J23: 12 | P23: 1 | Q23: =IFERROR(IF(O23="",0,O23*P23),0) -> 0
B24: Adjusted Rent | D24: =D60 -> 1090.075 | E24: =IFERROR(D24/(H8),0) -> 0.17412796 | J24: 13 | P24: 1 | Q24: =IFERROR(IF(O24="",0,O24*P24),0) -> 0
B25: Investment | D25: =D63 -> 0 | E25: =IFERROR(D25/(H8),0) -> 0 | J25: 14 | P25: 1 | Q25: =IFERROR(IF(O25="",0,O25*P25),0) -> 0
B26: TOTAL Going Out | D26: =D64 -> 1436.945 | E26: =IFERROR(D26/(H8),0) -> 0.22953678 | J26: 15 | P26: 1 | Q26: =IFERROR(IF(O26="",0,O26*P26),0) -> 0
B27: 💵 Money Left Over | D27: =D65 -> 4823.25 | E27: =IFERROR(D27/(H8),0) -> 0.77046322 | J27: 16 | P27: 1 | Q27: =IFERROR(IF(O27="",0,O27*P27),0) -> 0
J28: 17 | P28: 1 | Q28: =IFERROR(IF(O28="",0,O28*P28),0) -> 0
B29: Card | D29: Total This Month $ | J29: 18 | P29: 1 | Q29: =IFERROR(IF(O29="",0,O29*P29),0) -> 0
B30: CFF | D30: =SUMIF(N12:N131,B30,O12:O131) -> 15.98 | J30: 19 | P30: 1 | Q30: =IFERROR(IF(O30="",0,O30*P30),0) -> 0
B31: CFU | D31: =SUMIF(N12:N131,B31,O12:O131) -> 0 | J31: 20 | P31: 1 | Q31: =IFERROR(IF(O31="",0,O31*P31),0) -> 0
B32: CSP | D32: =SUMIF(N12:N131,B32,O12:O131) -> 0 | J32: 21 | P32: 1 | Q32: =IFERROR(IF(O32="",0,O32*P32),0) -> 0
B33: Discover | D33: =SUMIF(N12:N131,B33,O12:O131) -> 41.25 | J33: 22 | P33: 1 | Q33: =IFERROR(IF(O33="",0,O33*P33),0) -> 0
B34: Citi | D34: =SUMIF(N12:N131,B34,O12:O131) -> 0 | J34: 23 | P34: 1 | Q34: =IFERROR(IF(O34="",0,O34*P34),0) -> 0
B35: Capital One | D35: =SUMIF(N12:N131,B35,O12:O131) -> 21.99 | J35: 24 | P35: 1 | Q35: =IFERROR(IF(O35="",0,O35*P35),0) -> 0
B36: WF | D36: =SUMIF(N12:N131,B36,O12:O131) -> 0 | J36: 25 | P36: 1 | Q36: =IFERROR(IF(O36="",0,O36*P36),0) -> 0
B37: Amazon Card | D37: =SUMIF(N12:N131,B37,O12:O131) -> 7.65 | J37: 26 | P37: 1 | Q37: =IFERROR(IF(O37="",0,O37*P37),0) -> 0
B38: Robinhood | D38: =SUMIF(N12:N131,B38,O12:O131) -> 195 | J38: 27 | P38: 1 | Q38: =IFERROR(IF(O38="",0,O38*P38),0) -> 0
B39: Cash | D39: =SUMIF(N12:N131,B39,O12:O131) -> 65 | J39: 28 | P39: 1 | Q39: =IFERROR(IF(O39="",0,O39*P39),0) -> 0
B40: Other | D40: =SUMIF(N12:N131,B40,O12:O131) -> 0 | J40: 29 | P40: 1 | Q40: =IFERROR(IF(O40="",0,O40*P40),0) -> 0
B41: TOTAL CC CHARGES | D41: =SUM(D30:D40) -> 346.87 | J41: 30 | P41: 1 | Q41: =IFERROR(IF(O41="",0,O41*P41),0) -> 0
J42: 31 | P42: 1 | Q42: =IFERROR(IF(O42="",0,O42*P42),0) -> 0
...

Sheet Aug 2026
B2: 💰 Aug 2026 — Expense Tracker
B3: LEFT: summaries auto-update | RIGHT: log every transaction | Blue cells = enter data
B5: ⚙️ SETTINGS
B6: Paycheck #1 (mid-mo) | D6: 2500 | F6: Paycheck #2 (end-mo) | H6: 2500
B7: Full Monthly Rent | D7: 2221.4 | F7: Your Rent Split % | H7: 0.5
B8: Monthly Savings Goal | D8: 500 | F8: Total Monthly Income | H8: =D6+H6+D9 -> 9823.25
B9: Carried Over (prior month) | D9: ='Jul 2026'!D65 -> 4823.25
B10: 📊 CATEGORY SUMMARY | J10: 📋 EXPENSE LOG — Enter every transaction here
B11: Category | D11: Your Share $ | E11: % Income | F11: Budget $ | G11: vs Budget | J11: # | K11: Date | L11: Description | M11: Category | N11: Credit Card | O11: Total $ | P11: Split % | Q11: Your Share $ | R11: Notes / Memo | S11: Recurring?
B12: Groceries | D12: =SUMIF(M12:M131,B12,Q12:Q131) -> 0 | E12: =IFERROR(D12/(H8),0) -> 0 | F12: 300 | G12: =IF(D12=0,"",D12-F12) | J12: 1 | K12: 46235 | L12: Car Insurance | M12: Gas / Transport | N12: Cash | O12: 65 | P12: 1 | Q12: =IFERROR(IF(O12="",0,O12*P12),0) -> 65 | R12: Auto-pay | S12: Y
B13: Utilities | D13: =SUMIF(M12:M131,B13,Q12:Q131) -> 105.625 | E13: =IFERROR(D13/(H8),0) -> 0.010752551 | F13: 50 | G13: =IF(D13=0,"",D13-F13) -> 55.625 | J13: 2 | K13: 46235 | L13: Stronghold | M13: Health | N13: Robinhood | O13: 105 | P13: 1 | Q13: =IFERROR(IF(O13="",0,O13*P13),0) -> 105 | R13: Auto-pay | S13: Y
B14: Gas / Transport | D14: =SUMIF(M12:M131,B14,Q12:Q131) -> 65 | E14: =IFERROR(D14/(H8),0) -> 0.0066169547 | F14: 200 | G14: =IF(D14=0,"",D14-F14) -> -135 | J14: 3 | K14: 46235 | L14: Spectrum Internet | M14: Utilities | N14: Discover | O14: 41.25 | P14: 0.5 | Q14: =IFERROR(IF(O14="",0,O14*P14),0) -> 20.625 | R14: Auto-pay | S14: Y
B15: Dining / Takeout | D15: =SUMIF(M12:M131,B15,Q12:Q131) -> 0 | E15: =IFERROR(D15/(H8),0) -> 0 | F15: 300 | G15: =IF(D15=0,"",D15-F15) | J15: 4 | K15: 46235 | L15: Amazon Prime | M15: Subscriptions | N15: Amazon Card | O15: 7.65 | P15: 1 | Q15: =IFERROR(IF(O15="",0,O15*P15),0) -> 7.65 | R15: Auto-pay | S15: Y
B16: Entertainment | D16: =SUMIF(M12:M131,B16,Q12:Q131) -> 0 | E16: =IFERROR(D16/(H8),0) -> 0 | F16: 150 | G16: =IF(D16=0,"",D16-F16) | J16: 5 | K16: 46235 | L16: Spotify | M16: Subscriptions | N16: Capital One | O16: 21.99 | P16: 1 | Q16: =IFERROR(IF(O16="",0,O16*P16),0) -> 21.99 | R16: Auto-pay | S16: Y
B17: Health | D17: =SUMIF(M12:M131,B17,Q12:Q131) -> 105 | E17: =IFERROR(D17/(H8),0) -> 0.010688927 | F17: 200 | G17: =IF(D17=0,"",D17-F17) -> -95 | J17: 6 | K17: 46235 | L17: Electricity | M17: Utilities | O17: 170 | P17: 0.5 | Q17: =IFERROR(IF(O17="",0,O17*P17),0) -> 85 | R17: She pays | S17: Y
B18: Shopping | D18: =SUMIF(M12:M131,B18,Q12:Q131) -> 0 | E18: =IFERROR(D18/(H8),0) -> 0 | F18: 200 | G18: =IF(D18=0,"",D18-F18) | J18: 7 | K18: 46235 | L18: Twitch Sub | M18: Subscriptions | N18: CFF | O18: 5.99 | P18: 1 | Q18: =IFERROR(IF(O18="",0,O18*P18),0) -> 5.99 | R18: Auto-pay | S18: Y
B19: Subscriptions | D19: =SUMIF(M12:M131,B19,Q12:Q131) -> 65.62 | E19: =IFERROR(D19/(H8),0) -> 0.0066800702 | F19: 100 | G19: =IF(D19=0,"",D19-F19) -> -34.38 | J19: 8 | K19: 46235 | L19: Claude AI | M19: Subscriptions | N19: Robinhood | O19: 20 | P19: 1 | Q19: =IFERROR(IF(O19="",0,O19*P19),0) -> 20 | R19: Auto-pay | S19: Y
B20: Cash | D20: =SUMIF(M12:M131,B20,Q12:Q131) -> 0 | E20: =IFERROR(D20/(H8),0) -> 0 | F20: 100 | G20: =IF(D20=0,"",D20-F20) | J20: 9 | K20: 46235 | L20: Discord | M20: Subscriptions | N20: CFF | O20: 9.99 | P20: 1 | Q20: =IFERROR(IF(O20="",0,O20*P20),0) -> 9.99 | R20: Auto-pay | S20: Y
B21: Personal / Misc | D21: =SUMIF(M12:M131,B21,Q12:Q131) -> 0 | E21: =IFERROR(D21/(H8),0) -> 0 | F21: 50 | G21: =IF(D21=0,"",D21-F21) | J21: 10 | K21: 46241 | L21: DMV renewal | M21: Other | N21: Robinhood | O21: 169 | P21: 1 | Q21: 169 | S21: TRUE
B22: Other | D22: =SUMIF(M12:M131,B22,Q12:Q131) -> 169 | E22: =IFERROR(D22/(H8),0) -> 0.017204082 | F22: 50 | G22: =IF(D22=0,"",D22-F22) -> 119 | J22: 11 | P22: 1 | Q22: =IFERROR(IF(O22="",0,O22*P22),0) -> 0
B23: Travel | D23: =SUMIF($M$12:$M$131,B23,$Q$12:$Q$131) -> 0 | E23: =IFERROR(D23/(H8),0) -> 0 | J23: 12 | P23: 1 | Q23: =IFERROR(IF(O23="",0,O23*P23),0) -> 0
B24: Adjusted Rent | D24: =D60 -> 1175.075 | E24: =IFERROR(D24/(H8),0) -> 0.11962182 | J24: 13 | P24: 1 | Q24: =IFERROR(IF(O24="",0,O24*P24),0) -> 0
B25: Investment | D25: =D63 -> 0 | E25: =IFERROR(D25/(H8),0) -> 0 | J25: 14 | P25: 1 | Q25: =IFERROR(IF(O25="",0,O25*P25),0) -> 0
B26: TOTAL Going Out | D26: =D64 -> 1620.945 | E26: =IFERROR(D26/(H8),0) -> 0.16501107 | J26: 15 | P26: 1 | Q26: =IFERROR(IF(O26="",0,O26*P26),0) -> 0
B27: 💵 Money Left Over | D27: =D65 -> 8202.305 | E27: =IFERROR(D27/(H8),0) -> 0.83498893 | J27: 16 | P27: 1 | Q27: =IFERROR(IF(O27="",0,O27*P27),0) -> 0
J28: 17 | P28: 1 | Q28: =IFERROR(IF(O28="",0,O28*P28),0) -> 0
B29: Card | D29: Total This Month $ | J29: 18 | P29: 1 | Q29: =IFERROR(IF(O29="",0,O29*P29),0) -> 0
B30: CFF | D30: =SUMIF(N12:N131,B30,O12:O131) -> 15.98 | J30: 19 | P30: 1 | Q30: =IFERROR(IF(O30="",0,O30*P30),0) -> 0
B31: CFU | D31: =SUMIF(N12:N131,B31,O12:O131) -> 0 | J31: 20 | P31: 1 | Q31: =IFERROR(IF(O31="",0,O31*P31),0) -> 0
B32: CSP | D32: =SUMIF(N12:N131,B32,O12:O131) -> 0 | J32: 21 | P32: 1 | Q32: =IFERROR(IF(O32="",0,O32*P32),0) -> 0
B33: Discover | D33: =SUMIF(N12:N131,B33,O12:O131) -> 41.25 | J33: 22 | P33: 1 | Q33: =IFERROR(IF(O33="",0,O33*P33),0) -> 0
B34: Citi | D34: =SUMIF(N12:N131,B34,O12:O131) -> 0 | J34: 23 | P34: 1 | Q34: =IFERROR(IF(O34="",0,O34*P34),0) -> 0
B35: Capital One | D35: =SUMIF(N12:N131,B35,O12:O131) -> 21.99 | J35: 24 | P35: 1 | Q35: =IFERROR(IF(O35="",0,O35*P35),0) -> 0
B36: WF | D36: =SUMIF(N12:N131,B36,O12:O131) -> 0 | J36: 25 | P36: 1 | Q36: =IFERROR(IF(O36="",0,O36*P36),0) -> 0
B37: Amazon Card | D37: =SUMIF(N12:N131,B37,O12:O131) -> 7.65 | J37: 26 | P37: 1 | Q37: =IFERROR(IF(O37="",0,O37*P37),0) -> 0
B38: Robinhood | D38: =SUMIF(N12:N131,B38,O12:O131) -> 294 | J38: 27 | P38: 1 | Q38: =IFERROR(IF(O38="",0,O38*P38),0) -> 0
B39: Cash | D39: =SUMIF(N12:N131,B39,O12:O131) -> 65 | J39: 28 | P39: 1 | Q39: =IFERROR(IF(O39="",0,O39*P39),0) -> 0
B40: Other | D40: =SUMIF(N12:N131,B40,O12:O131) -> 0 | J40: 29 | P40: 1 | Q40: =IFERROR(IF(O40="",0,O40*P40),0) -> 0
B41: TOTAL CC CHARGES | D41: =SUM(D30:D40) -> 445.87 | J41: 30 | P41: 1 | Q41: =IFERROR(IF(O41="",0,O41*P41),0) -> 0
J42: 31 | P42: 1 | Q42: =IFERROR(IF(O42="",0,O42*P42),0) -> 0
...

Sheet Sep 2026
B2: 💰 Sep 2026 — Expense Tracker
B3: LEFT: summaries auto-update | RIGHT: log every transaction | Blue cells = enter data
B5: ⚙️ SETTINGS
B6: Paycheck #1 (mid-mo) | D6: 2500 | F6: Paycheck #2 (end-mo) | H6: 2500
B7: Full Monthly Rent | D7: 2221.4 | F7: Your Rent Split % | H7: 0.5
B8: Monthly Savings Goal | D8: 500 | F8: Total Monthly Income | H8: =D6+H6+D9 -> 13202.305
B9: Carried Over (prior month) | D9: ='Aug 2026'!D65 -> 8202.305
B10: 📊 CATEGORY SUMMARY | J10: 📋 EXPENSE LOG — Enter every transaction here
B11: Category | D11: Your Share $ | E11: % Income | F11: Budget $ | G11: vs Budget | J11: # | K11: Date | L11: Description | M11: Category | N11: Credit Card | O11: Total $ | P11: Split % | Q11: Your Share $ | R11: Notes / Memo | S11: Recurring?
B12: Groceries | D12: =SUMIF(M12:M131,B12,Q12:Q131) -> 0 | E12: =IFERROR(D12/(H8),0) -> 0 | F12: 300 | G12: =IF(D12=0,"",D12-F12) | J12: 1 | K12: 46266 | L12: Car Insurance | M12: Gas / Transport | N12: Cash | O12: 65 | P12: 1 | Q12: =IFERROR(IF(O12="",0,O12*P12),0) -> 65 | R12: Auto-pay | S12: Y
B13: Utilities | D13: =SUMIF(M12:M131,B13,Q12:Q131) -> 20.625 | E13: =IFERROR(D13/(H8),0) -> 0.0015622272 | F13: 50 | G13: =IF(D13=0,"",D13-F13) -> -29.375 | J13: 2 | K13: 46266 | L13: Stronghold | M13: Health | N13: Robinhood | O13: 105 | P13: 1 | Q13: =IFERROR(IF(O13="",0,O13*P13),0) -> 105 | R13: Auto-pay | S13: Y
B14: Gas / Transport | D14: =SUMIF(M12:M131,B14,Q12:Q131) -> 65 | E14: =IFERROR(D14/(H8),0) -> 0.0049233827 | F14: 200 | G14: =IF(D14=0,"",D14-F14) -> -135 | J14: 3 | K14: 46266 | L14: Spectrum Internet | M14: Utilities | N14: Discover | O14: 41.25 | P14: 0.5 | Q14: =IFERROR(IF(O14="",0,O14*P14),0) -> 20.625 | R14: Auto-pay | S14: Y
B15: Dining / Takeout | D15: =SUMIF(M12:M131,B15,Q12:Q131) -> 0 | E15: =IFERROR(D15/(H8),0) -> 0 | F15: 300 | G15: =IF(D15=0,"",D15-F15) | J15: 4 | K15: 46266 | L15: Amazon Prime | M15: Subscriptions | N15: Amazon Card | O15: 7.65 | P15: 1 | Q15: =IFERROR(IF(O15="",0,O15*P15),0) -> 7.65 | R15: Auto-pay | S15: Y
B16: Entertainment | D16: =SUMIF(M12:M131,B16,Q12:Q131) -> 0 | E16: =IFERROR(D16/(H8),0) -> 0 | F16: 150 | G16: =IF(D16=0,"",D16-F16) | J16: 5 | K16: 46266 | L16: Spotify | M16: Subscriptions | N16: Capital One | O16: 21.99 | P16: 1 | Q16: =IFERROR(IF(O16="",0,O16*P16),0) -> 21.99 | R16: Auto-pay | S16: Y
B17: Health | D17: =SUMIF(M12:M131,B17,Q12:Q131) -> 105 | E17: =IFERROR(D17/(H8),0) -> 0.0079531567 | F17: 200 | G17: =IF(D17=0,"",D17-F17) -> -95 | J17: 6 | K17: 46266 | L17: Electricity | M17: Utilities | P17: 0.5 | Q17: =IFERROR(IF(O17="",0,O17*P17),0) -> 0 | R17: She pays | S17: Y
B18: Shopping | D18: =SUMIF(M12:M131,B18,Q12:Q131) -> 0 | E18: =IFERROR(D18/(H8),0) -> 0 | F18: 200 | G18: =IF(D18=0,"",D18-F18) | J18: 7 | K18: 46266 | L18: Twitch Sub | M18: Subscriptions | N18: CFF | O18: 5.99 | P18: 1 | Q18: =IFERROR(IF(O18="",0,O18*P18),0) -> 5.99 | R18: Auto-pay | S18: Y
B19: Subscriptions | D19: =SUMIF(M12:M131,B19,Q12:Q131) -> 65.62 | E19: =IFERROR(D19/(H8),0) -> 0.0049703442 | F19: 100 | G19: =IF(D19=0,"",D19-F19) -> -34.38 | J19: 8 | K19: 46266 | L19: Claude AI | M19: Subscriptions | N19: Robinhood | O19: 20 | P19: 1 | Q19: =IFERROR(IF(O19="",0,O19*P19),0) -> 20 | R19: Auto-pay | S19: Y
B20: Cash | D20: =SUMIF(M12:M131,B20,Q12:Q131) -> 0 | E20: =IFERROR(D20/(H8),0) -> 0 | F20: 100 | G20: =IF(D20=0,"",D20-F20) | J20: 9 | K20: 46266 | L20: Discord | M20: Subscriptions | N20: CFF | O20: 9.99 | P20: 1 | Q20: =IFERROR(IF(O20="",0,O20*P20),0) -> 9.99 | R20: Auto-pay | S20: Y
B21: Personal / Misc | D21: =SUMIF(M12:M131,B21,Q12:Q131) -> 0 | E21: =IFERROR(D21/(H8),0) -> 0 | F21: 50 | G21: =IF(D21=0,"",D21-F21) | J21: 10 | P21: 1 | Q21: =IFERROR(IF(O21="",0,O21*P21),0) -> 0
B22: Other | D22: =SUMIF(M12:M131,B22,Q12:Q131) -> 0 | E22: =IFERROR(D22/(H8),0) -> 0 | F22: 50 | G22: =IF(D22=0,"",D22-F22) | J22: 11 | P22: 1 | Q22: =IFERROR(IF(O22="",0,O22*P22),0) -> 0
B23: Travel | D23: =SUMIF($M$12:$M$131,B23,$Q$12:$Q$131) -> 0 | E23: =IFERROR(D23/(H8),0) -> 0 | J23: 12 | P23: 1 | Q23: =IFERROR(IF(O23="",0,O23*P23),0) -> 0
B24: Adjusted Rent | D24: =D60 -> 1090.075 | E24: =IFERROR(D24/(H8),0) -> 0.082567021 | J24: 13 | P24: 1 | Q24: =IFERROR(IF(O24="",0,O24*P24),0) -> 0
B25: Investment | D25: =D63 -> 0 | E25: =IFERROR(D25/(H8),0) -> 0 | J25: 14 | P25: 1 | Q25: =IFERROR(IF(O25="",0,O25*P25),0) -> 0
B26: TOTAL Going Out | D26: =D64 -> 1366.945 | E26: =IFERROR(D26/(H8),0) -> 0.10353836 | J26: 15 | P26: 1 | Q26: =IFERROR(IF(O26="",0,O26*P26),0) -> 0
B27: 💵 Money Left Over | D27: =D65 -> 11835.36 | E27: =IFERROR(D27/(H8),0) -> 0.89646164 | J27: 16 | P27: 1 | Q27: =IFERROR(IF(O27="",0,O27*P27),0) -> 0
J28: 17 | P28: 1 | Q28: =IFERROR(IF(O28="",0,O28*P28),0) -> 0
B29: Card | D29: Total This Month $ | J29: 18 | P29: 1 | Q29: =IFERROR(IF(O29="",0,O29*P29),0) -> 0
B30: CFF | D30: =SUMIF(N12:N131,B30,O12:O131) -> 15.98 | J30: 19 | P30: 1 | Q30: =IFERROR(IF(O30="",0,O30*P30),0) -> 0
B31: CFU | D31: =SUMIF(N12:N131,B31,O12:O131) -> 0 | J31: 20 | P31: 1 | Q31: =IFERROR(IF(O31="",0,O31*P31),0) -> 0
B32: CSP | D32: =SUMIF(N12:N131,B32,O12:O131) -> 0 | J32: 21 | P32: 1 | Q32: =IFERROR(IF(O32="",0,O32*P32),0) -> 0
B33: Discover | D33: =SUMIF(N12:N131,B33,O12:O131) -> 41.25 | J33: 22 | P33: 1 | Q33: =IFERROR(IF(O33="",0,O33*P33),0) -> 0
B34: Citi | D34: =SUMIF(N12:N131,B34,O12:O131) -> 0 | J34: 23 | P34: 1 | Q34: =IFERROR(IF(O34="",0,O34*P34),0) -> 0
B35: Capital One | D35: =SUMIF(N12:N131,B35,O12:O131) -> 21.99 | J35: 24 | P35: 1 | Q35: =IFERROR(IF(O35="",0,O35*P35),0) -> 0
B36: WF | D36: =SUMIF(N12:N131,B36,O12:O131) -> 0 | J36: 25 | P36: 1 | Q36: =IFERROR(IF(O36="",0,O36*P36),0) -> 0
B37: Amazon Card | D37: =SUMIF(N12:N131,B37,O12:O131) -> 7.65 | J37: 26 | P37: 1 | Q37: =IFERROR(IF(O37="",0,O37*P37),0) -> 0
B38: Robinhood | D38: =SUMIF(N12:N131,B38,O12:O131) -> 125 | J38: 27 | P38: 1 | Q38: =IFERROR(IF(O38="",0,O38*P38),0) -> 0
B39: Cash | D39: =SUMIF(N12:N131,B39,O12:O131) -> 65 | J39: 28 | P39: 1 | Q39: =IFERROR(IF(O39="",0,O39*P39),0) -> 0
B40: Other | D40: =SUMIF(N12:N131,B40,O12:O131) -> 0 | J40: 29 | P40: 1 | Q40: =IFERROR(IF(O40="",0,O40*P40),0) -> 0
B41: TOTAL CC CHARGES | D41: =SUM(D30:D40) -> 276.87 | J41: 30 | P41: 1 | Q41: =IFERROR(IF(O41="",0,O41*P41),0) -> 0
J42: 31 | P42: 1 | Q42: =IFERROR(IF(O42="",0,O42*P42),0) -> 0
...

Sheet Oct 2026
B2: 💰 Oct 2026 — Expense Tracker
B3: LEFT: summaries auto-update | RIGHT: log every transaction | Blue cells = enter data
B5: ⚙️ SETTINGS
B6: Paycheck #1 (mid-mo) | D6: 2500 | F6: Paycheck #2 (end-mo) | H6: 2500
B7: Full Monthly Rent | D7: 2221.4 | F7: Your Rent Split % | H7: 0.5
B8: Monthly Savings Goal | D8: 500 | F8: Total Monthly Income | H8: =D6+H6+D9 -> 16835.36
B9: Carried Over (prior month) | D9: ='Sep 2026'!D65 -> 11835.36
B10: 📊 CATEGORY SUMMARY | J10: 📋 EXPENSE LOG — Enter every transaction here
B11: Category | D11: Your Share $ | E11: % Income | F11: Budget $ | G11: vs Budget | J11: # | K11: Date | L11: Description | M11: Category | N11: Credit Card | O11: Total $ | P11: Split % | Q11: Your Share $ | R11: Notes / Memo | S11: Recurring?
B12: Groceries | D12: =SUMIF(M12:M131,B12,Q12:Q131) -> 0 | E12: =IFERROR(D12/(H8),0) -> 0 | F12: 300 | G12: =IF(D12=0,"",D12-F12) | J12: 1 | K12: 46296 | L12: Car Insurance | M12: Gas / Transport | N12: Cash | O12: 65 | P12: 1 | Q12: =IFERROR(IF(O12="",0,O12*P12),0) -> 65 | R12: Auto-pay | S12: Y
B13: Utilities | D13: =SUMIF(M12:M131,B13,Q12:Q131) -> 105.625 | E13: =IFERROR(D13/(H8),0) -> 0.0062739971 | F13: 50 | G13: =IF(D13=0,"",D13-F13) -> 55.625 | J13: 2 | K13: 46296 | L13: Stronghold | M13: Health | N13: Robinhood | O13: 105 | P13: 1 | Q13: =IFERROR(IF(O13="",0,O13*P13),0) -> 105 | R13: Auto-pay | S13: Y
B14: Gas / Transport | D14: =SUMIF(M12:M131,B14,Q12:Q131) -> 65 | E14: =IFERROR(D14/(H8),0) -> 0.0038609213 | F14: 200 | G14: =IF(D14=0,"",D14-F14) -> -135 | J14: 3 | K14: 46296 | L14: Spectrum Internet | M14: Utilities | N14: Discover | O14: 41.25 | P14: 0.5 | Q14: =IFERROR(IF(O14="",0,O14*P14),0) -> 20.625 | R14: Auto-pay | S14: Y
B15: Dining / Takeout | D15: =SUMIF(M12:M131,B15,Q12:Q131) -> 0 | E15: =IFERROR(D15/(H8),0) -> 0 | F15: 300 | G15: =IF(D15=0,"",D15-F15) | J15: 4 | K15: 46296 | L15: Amazon Prime | M15: Subscriptions | N15: Amazon Card | O15: 7.65 | P15: 1 | Q15: =IFERROR(IF(O15="",0,O15*P15),0) -> 7.65 | R15: Auto-pay | S15: Y
B16: Entertainment | D16: =SUMIF(M12:M131,B16,Q12:Q131) -> 0 | E16: =IFERROR(D16/(H8),0) -> 0 | F16: 150 | G16: =IF(D16=0,"",D16-F16) | J16: 5 | K16: 46296 | L16: Spotify | M16: Subscriptions | N16: Capital One | O16: 21.99 | P16: 1 | Q16: =IFERROR(IF(O16="",0,O16*P16),0) -> 21.99 | R16: Auto-pay | S16: Y
B17: Health | D17: =SUMIF(M12:M131,B17,Q12:Q131) -> 105 | E17: =IFERROR(D17/(H8),0) -> 0.0062368729 | F17: 200 | G17: =IF(D17=0,"",D17-F17) -> -95 | J17: 6 | K17: 46296 | L17: Electricity | M17: Utilities | O17: 170 | P17: 0.5 | Q17: =IFERROR(IF(O17="",0,O17*P17),0) -> 85 | R17: She pays | S17: Y
B18: Shopping | D18: =SUMIF(M12:M131,B18,Q12:Q131) -> 0 | E18: =IFERROR(D18/(H8),0) -> 0 | F18: 200 | G18: =IF(D18=0,"",D18-F18) | J18: 7 | K18: 46296 | L18: Twitch Sub | M18: Subscriptions | N18: CFF | O18: 5.99 | P18: 1 | Q18: =IFERROR(IF(O18="",0,O18*P18),0) -> 5.99 | R18: Auto-pay | S18: Y
B19: Subscriptions | D19: =SUMIF(M12:M131,B19,Q12:Q131) -> 65.62 | E19: =IFERROR(D19/(H8),0) -> 0.0038977485 | F19: 100 | G19: =IF(D19=0,"",D19-F19) -> -34.38 | J19: 8 | K19: 46296 | L19: Claude AI | M19: Subscriptions | N19: Robinhood | O19: 20 | P19: 1 | Q19: =IFERROR(IF(O19="",0,O19*P19),0) -> 20 | R19: Auto-pay | S19: Y
B20: Cash | D20: =SUMIF(M12:M131,B20,Q12:Q131) -> 0 | E20: =IFERROR(D20/(H8),0) -> 0 | F20: 100 | G20: =IF(D20=0,"",D20-F20) | J20: 9 | K20: 46296 | L20: Discord | M20: Subscriptions | N20: CFF | O20: 9.99 | P20: 1 | Q20: =IFERROR(IF(O20="",0,O20*P20),0) -> 9.99 | R20: Auto-pay | S20: Y
B21: Personal / Misc | D21: =SUMIF(M12:M131,B21,Q12:Q131) -> 0 | E21: =IFERROR(D21/(H8),0) -> 0 | F21: 50 | G21: =IF(D21=0,"",D21-F21) | J21: 10 | P21: 1 | Q21: =IFERROR(IF(O21="",0,O21*P21),0) -> 0
B22: Other | D22: =SUMIF(M12:M131,B22,Q12:Q131) -> 0 | E22: =IFERROR(D22/(H8),0) -> 0 | F22: 50 | G22: =IF(D22=0,"",D22-F22) | J22: 11 | P22: 1 | Q22: =IFERROR(IF(O22="",0,O22*P22),0) -> 0
B23: Travel | D23: =SUMIF($M$12:$M$131,B23,$Q$12:$Q$131) -> 0 | E23: =IFERROR(D23/(H8),0) -> 0 | J23: 12 | P23: 1 | Q23: =IFERROR(IF(O23="",0,O23*P23),0) -> 0
B24: Adjusted Rent | D24: =D60 -> 1175.075 | E24: =IFERROR(D24/(H8),0) -> 0.069798032 | J24: 13 | P24: 1 | Q24: =IFERROR(IF(O24="",0,O24*P24),0) -> 0
B25: Investment | D25: =D63 -> 0 | E25: =IFERROR(D25/(H8),0) -> 0 | J25: 14 | P25: 1 | Q25: =IFERROR(IF(O25="",0,O25*P25),0) -> 0
B26: TOTAL Going Out | D26: =D64 -> 1451.945 | E26: =IFERROR(D26/(H8),0) -> 0.086243775 | J26: 15 | P26: 1 | Q26: =IFERROR(IF(O26="",0,O26*P26),0) -> 0
B27: 💵 Money Left Over | D27: =D65 -> 15383.415 | E27: =IFERROR(D27/(H8),0) -> 0.91375622 | J27: 16 | P27: 1 | Q27: =IFERROR(IF(O27="",0,O27*P27),0) -> 0
J28: 17 | P28: 1 | Q28: =IFERROR(IF(O28="",0,O28*P28),0) -> 0
B29: Card | D29: Total This Month $ | J29: 18 | P29: 1 | Q29: =IFERROR(IF(O29="",0,O29*P29),0) -> 0
B30: CFF | D30: =SUMIF(N12:N131,B30,O12:O131) -> 15.98 | J30: 19 | P30: 1 | Q30: =IFERROR(IF(O30="",0,O30*P30),0) -> 0
B31: CFU | D31: =SUMIF(N12:N131,B31,O12:O131) -> 0 | J31: 20 | P31: 1 | Q31: =IFERROR(IF(O31="",0,O31*P31),0) -> 0
B32: CSP | D32: =SUMIF(N12:N131,B32,O12:O131) -> 0 | J32: 21 | P32: 1 | Q32: =IFERROR(IF(O32="",0,O32*P32),0) -> 0
B33: Discover | D33: =SUMIF(N12:N131,B33,O12:O131) -> 41.25 | J33: 22 | P33: 1 | Q33: =IFERROR(IF(O33="",0,O33*P33),0) -> 0
B34: Citi | D34: =SUMIF(N12:N131,B34,O12:O131) -> 0 | J34: 23 | P34: 1 | Q34: =IFERROR(IF(O34="",0,O34*P34),0) -> 0
B35: Capital One | D35: =SUMIF(N12:N131,B35,O12:O131) -> 21.99 | J35: 24 | P35: 1 | Q35: =IFERROR(IF(O35="",0,O35*P35),0) -> 0
B36: WF | D36: =SUMIF(N12:N131,B36,O12:O131) -> 0 | J36: 25 | P36: 1 | Q36: =IFERROR(IF(O36="",0,O36*P36),0) -> 0
B37: Amazon Card | D37: =SUMIF(N12:N131,B37,O12:O131) -> 7.65 | J37: 26 | P37: 1 | Q37: =IFERROR(IF(O37="",0,O37*P37),0) -> 0
B38: Robinhood | D38: =SUMIF(N12:N131,B38,O12:O131) -> 125 | J38: 27 | P38: 1 | Q38: =IFERROR(IF(O38="",0,O38*P38),0) -> 0
